30/10/21 (11:19:07) | ERROR: <urlopen error _ssl.c:1112: The handshake operation timed out>
Traceback (most recent call last):
  File "/usr/lib/python3.9/urllib/request.py", line 1346, in do_open
    h.request(req.get_method(), req.selector, req.data, headers,
  File "/usr/lib/python3.9/http/client.py", line 1279, in request
    self._send_request(method, url, body, headers, encode_chunked)
  File "/usr/lib/python3.9/http/client.py", line 1325, in _send_request
    self.endheaders(body, encode_chunked=encode_chunked)
  File "/usr/lib/python3.9/http/client.py", line 1274, in endheaders
    self._send_output(message_body, encode_chunked=encode_chunked)
  File "/usr/lib/python3.9/http/client.py", line 1034, in _send_output
    self.send(msg)
  File "/usr/lib/python3.9/http/client.py", line 974, in send
    self.connect()
  File "/usr/lib/python3.9/http/client.py", line 1448, in connect
    self.sock = self._context.wrap_socket(self.sock,
  File "/usr/lib/python3.9/ssl.py", line 500, in wrap_socket
    return self.sslsocket_class._create(
  File "/usr/lib/python3.9/ssl.py", line 1040, in _create
    self.do_handshake()
  File "/usr/lib/python3.9/ssl.py", line 1309, in do_handshake
    self._sslobj.do_handshake()
socket.timeout: _ssl.c:1112: The handshake operation timed out

During handling of the above exception, another exception occurred:

Traceback (most recent call last):
  File "/sbin/bpytop", line 5009, in _checker
    with urllib.request.urlopen("https://github.com/aristocratos/bpytop/raw/master/bpytop.py", timeout=5) as source: # type: ignore
  File "/usr/lib/python3.9/urllib/request.py", line 214, in urlopen
    return opener.open(url, data, timeout)
  File "/usr/lib/python3.9/urllib/request.py", line 517, in open
    response = self._open(req, data)
  File "/usr/lib/python3.9/urllib/request.py", line 534, in _open
    result = self._call_chain(self.handle_open, protocol, protocol +
  File "/usr/lib/python3.9/urllib/request.py", line 494, in _call_chain
    result = func(*args)
  File "/usr/lib/python3.9/urllib/request.py", line 1389, in https_open
    return self.do_open(http.client.HTTPSConnection, req,
  File "/usr/lib/python3.9/urllib/request.py", line 1349, in do_open
    raise URLError(err)
urllib.error.URLError: <urlopen error _ssl.c:1112: The handshake operation timed out>
19/11/21 (20:47:28) | ERROR: [Errno 2] No such file or directory: '/home/pu/.config/bpytop/themes'
Traceback (most recent call last):
  File "/sbin/bpytop", line 1337, in refresh
    for f in os.listdir(d):
FileNotFoundError: [Errno 2] No such file or directory: '/home/pu/.config/bpytop/themes'
19/11/21 (23:11:07) | ERROR: [Errno 2] No such file or directory: '/home/pu/.config/bpytop/themes'
Traceback (most recent call last):
  File "/sbin/bpytop", line 1337, in refresh
    for f in os.listdir(d):
FileNotFoundError: [Errno 2] No such file or directory: '/home/pu/.config/bpytop/themes'
19/11/21 (23:11:19) | ERROR: <urlopen error _ssl.c:1112: The handshake operation timed out>
Traceback (most recent call last):
  File "/usr/lib/python3.9/urllib/request.py", line 1346, in do_open
    h.request(req.get_method(), req.selector, req.data, headers,
  File "/usr/lib/python3.9/http/client.py", line 1279, in request
    self._send_request(method, url, body, headers, encode_chunked)
  File "/usr/lib/python3.9/http/client.py", line 1325, in _send_request
    self.endheaders(body, encode_chunked=encode_chunked)
  File "/usr/lib/python3.9/http/client.py", line 1274, in endheaders
    self._send_output(message_body, encode_chunked=encode_chunked)
  File "/usr/lib/python3.9/http/client.py", line 1034, in _send_output
    self.send(msg)
  File "/usr/lib/python3.9/http/client.py", line 974, in send
    self.connect()
  File "/usr/lib/python3.9/http/client.py", line 1448, in connect
    self.sock = self._context.wrap_socket(self.sock,
  File "/usr/lib/python3.9/ssl.py", line 500, in wrap_socket
    return self.sslsocket_class._create(
  File "/usr/lib/python3.9/ssl.py", line 1040, in _create
    self.do_handshake()
  File "/usr/lib/python3.9/ssl.py", line 1309, in do_handshake
    self._sslobj.do_handshake()
socket.timeout: _ssl.c:1112: The handshake operation timed out

During handling of the above exception, another exception occurred:

Traceback (most recent call last):
  File "/sbin/bpytop", line 5009, in _checker
    with urllib.request.urlopen("https://github.com/aristocratos/bpytop/raw/master/bpytop.py", timeout=5) as source: # type: ignore
  File "/usr/lib/python3.9/urllib/request.py", line 214, in urlopen
    return opener.open(url, data, timeout)
  File "/usr/lib/python3.9/urllib/request.py", line 523, in open
    response = meth(req, response)
  File "/usr/lib/python3.9/urllib/request.py", line 632, in http_response
    response = self.parent.error(
  File "/usr/lib/python3.9/urllib/request.py", line 555, in error
    result = self._call_chain(*args)
  File "/usr/lib/python3.9/urllib/request.py", line 494, in _call_chain
    result = func(*args)
  File "/usr/lib/python3.9/urllib/request.py", line 747, in http_error_302
    return self.parent.open(new, timeout=req.timeout)
  File "/usr/lib/python3.9/urllib/request.py", line 517, in open
    response = self._open(req, data)
  File "/usr/lib/python3.9/urllib/request.py", line 534, in _open
    result = self._call_chain(self.handle_open, protocol, protocol +
  File "/usr/lib/python3.9/urllib/request.py", line 494, in _call_chain
    result = func(*args)
  File "/usr/lib/python3.9/urllib/request.py", line 1389, in https_open
    return self.do_open(http.client.HTTPSConnection, req,
  File "/usr/lib/python3.9/urllib/request.py", line 1349, in do_open
    raise URLError(err)
urllib.error.URLError: <urlopen error _ssl.c:1112: The handshake operation timed out>
27/11/21 (10:39:18) | ERROR: [Errno 2] No such file or directory: '/home/pu/.config/bpytop/themes'
Traceback (most recent call last):
  File "/sbin/bpytop", line 1337, in refresh
    for f in os.listdir(d):
FileNotFoundError: [Errno 2] No such file or directory: '/home/pu/.config/bpytop/themes'
27/11/21 (18:50:32) | ERROR: [Errno 2] No such file or directory: '/home/pu/.config/bpytop/themes'
Traceback (most recent call last):
  File "/sbin/bpytop", line 1337, in refresh
    for f in os.listdir(d):
FileNotFoundError: [Errno 2] No such file or directory: '/home/pu/.config/bpytop/themes'
03/12/21 (19:49:03) | ERROR: [Errno 2] No such file or directory: '/home/pu/.config/bpytop/themes'
Traceback (most recent call last):
  File "/sbin/bpytop", line 1337, in refresh
    for f in os.listdir(d):
FileNotFoundError: [Errno 2] No such file or directory: '/home/pu/.config/bpytop/themes'
